24-06-2022 00:23:21 - [ERROR] -  files_loader - (files_loader.py).read_json(line 35) - File not found.
Traceback (most recent call last):
  File "/home/user/Desktop/Agritech/scripts/files_loader.py", line 29, in read_json
    with open(json_path) as js:
FileNotFoundError: [Errno 2] No such file or directory: './getdata.json'
24-06-2022 00:25:09 - [ERROR] -  files_loader - (files_loader.py).read_json(line 35) - File not found.
Traceback (most recent call last):
  File "/home/user/Desktop/Agritech/scripts/files_loader.py", line 29, in read_json
    with open(json_path) as js:
FileNotFoundError: [Errno 2] No such file or directory: './getdata.json'
24-06-2022 00:25:09 - [ERROR] -  files_loader - (files_loader.py).read_json(line 35) - File not found.
Traceback (most recent call last):
  File "/home/user/Desktop/Agritech/scripts/files_loader.py", line 29, in read_json
    with open(json_path) as js:
FileNotFoundError: [Errno 2] No such file or directory: './getdata.json'
24-06-2022 00:27:34 - [ERROR] -  files_loader - (files_loader.py).read_json(line 35) - File not found.
Traceback (most recent call last):
  File "/home/user/Desktop/Agritech/scripts/files_loader.py", line 29, in read_json
    with open(json_path) as js:
FileNotFoundError: [Errno 2] No such file or directory: './fetch.json'
24-06-2022 00:27:34 - [ERROR] -  files_loader - (files_loader.py).read_json(line 35) - File not found.
Traceback (most recent call last):
  File "/home/user/Desktop/Agritech/scripts/files_loader.py", line 29, in read_json
    with open(json_path) as js:
FileNotFoundError: [Errno 2] No such file or directory: './fetch.json'
24-06-2022 00:27:34 - [ERROR] -  files_loader - (files_loader.py).read_json(line 35) - File not found.
Traceback (most recent call last):
  File "/home/user/Desktop/Agritech/scripts/files_loader.py", line 29, in read_json
    with open(json_path) as js:
FileNotFoundError: [Errno 2] No such file or directory: './fetch.json'
24-06-2022 00:27:36 - [ERROR] -  files_loader - (files_loader.py).read_json(line 35) - File not found.
Traceback (most recent call last):
  File "/home/user/Desktop/Agritech/scripts/files_loader.py", line 29, in read_json
    with open(json_path) as js:
FileNotFoundError: [Errno 2] No such file or directory: './fetch.json'
24-06-2022 00:27:36 - [ERROR] -  files_loader - (files_loader.py).read_json(line 35) - File not found.
Traceback (most recent call last):
  File "/home/user/Desktop/Agritech/scripts/files_loader.py", line 29, in read_json
    with open(json_path) as js:
FileNotFoundError: [Errno 2] No such file or directory: './fetch.json'
24-06-2022 00:27:36 - [ERROR] -  files_loader - (files_loader.py).read_json(line 35) - File not found.
Traceback (most recent call last):
  File "/home/user/Desktop/Agritech/scripts/files_loader.py", line 29, in read_json
    with open(json_path) as js:
FileNotFoundError: [Errno 2] No such file or directory: './fetch.json'
24-06-2022 00:27:36 - [ERROR] -  files_loader - (files_loader.py).read_json(line 35) - File not found.
Traceback (most recent call last):
  File "/home/user/Desktop/Agritech/scripts/files_loader.py", line 29, in read_json
    with open(json_path) as js:
FileNotFoundError: [Errno 2] No such file or directory: './fetch.json'
24-06-2022 00:42:17 - [INFO] -  files_loader - (files_loader.py).read_json(line 31) - Json file read from fetch.json.
24-06-2022 00:42:17 - [INFO] -  files_loader - (files_loader.py).read_json(line 31) - Json file read from fetch.json.
24-06-2022 00:42:17 - [INFO] -  files_loader - (files_loader.py).read_json(line 31) - Json file read from fetch.json.
24-06-2022 00:42:17 - [INFO] -  files_loader - (files_loader.py).read_json(line 31) - Json file read from fetch.json.
24-06-2022 00:42:17 - [INFO] -  files_loader - (files_loader.py).read_json(line 31) - Json file read from fetch.json.
24-06-2022 00:42:29 - [INFO] -  files_loader - (files_loader.py).read_json(line 31) - Json file read from fetch.json.
24-06-2022 00:42:29 - [INFO] -  files_loader - (files_loader.py).read_json(line 31) - Json file read from fetch.json.
24-06-2022 00:42:29 - [INFO] -  files_loader - (files_loader.py).read_json(line 31) - Json file read from fetch.json.
24-06-2022 00:42:29 - [INFO] -  files_loader - (files_loader.py).read_json(line 31) - Json file read from fetch.json.
24-06-2022 00:42:29 - [INFO] -  files_loader - (files_loader.py).read_json(line 31) - Json file read from fetch.json.
24-06-2022 00:42:29 - [INFO] -  files_loader - (files_loader.py).read_json(line 31) - Json file read from fetch.json.
24-06-2022 00:45:10 - [INFO] -  files_loader - (files_loader.py).read_json(line 31) - Json file read from fetch.json.
24-06-2022 00:45:10 - [INFO] -  files_loader - (files_loader.py).read_json(line 31) - Json file read from fetch.json.
24-06-2022 00:45:10 - [INFO] -  files_loader - (files_loader.py).read_json(line 31) - Json file read from fetch.json.
24-06-2022 00:45:10 - [INFO] -  files_loader - (files_loader.py).read_json(line 31) - Json file read from fetch.json.
24-06-2022 00:45:10 - [INFO] -  files_loader - (files_loader.py).read_json(line 31) - Json file read from fetch.json.
24-06-2022 00:45:10 - [INFO] -  files_loader - (files_loader.py).read_json(line 31) - Json file read from fetch.json.
24-06-2022 00:45:10 - [INFO] -  files_loader - (files_loader.py).read_json(line 31) - Json file read from fetch.json.
24-06-2022 00:46:30 - [INFO] -  files_loader - (files_loader.py).read_json(line 31) - Json file read from fetch.json.
24-06-2022 00:46:30 - [INFO] -  files_loader - (files_loader.py).read_json(line 31) - Json file read from fetch.json.
24-06-2022 00:46:30 - [INFO] -  files_loader - (files_loader.py).read_json(line 31) - Json file read from fetch.json.
24-06-2022 00:46:30 - [INFO] -  files_loader - (files_loader.py).read_json(line 31) - Json file read from fetch.json.
24-06-2022 00:46:30 - [INFO] -  files_loader - (files_loader.py).read_json(line 31) - Json file read from fetch.json.
24-06-2022 00:46:30 - [INFO] -  files_loader - (files_loader.py).read_json(line 31) - Json file read from fetch.json.
24-06-2022 00:46:30 - [INFO] -  files_loader - (files_loader.py).read_json(line 31) - Json file read from fetch.json.
24-06-2022 00:46:30 - [INFO] -  files_loader - (files_loader.py).read_json(line 31) - Json file read from fetch.json.
24-06-2022 00:46:32 - [ERROR] -  __main__ - (<ipython-input-39-4b0165ac5391>).run_pipeline(line 54) - Pipeline execution failed
Traceback (most recent call last):
  File "<ipython-input-39-4b0165ac5391>", line 50, in run_pipeline
    pipeline.execute()
  File "/home/user/anaconda3/envs/agritech/lib/python3.6/site-packages/pdal/pipeline.py", line 40, in execute
    return self.p.execute()
  File "libpdalpython.pyx", line 180, in pdal.libpdalpython.PyPipeline.execute
RuntimeError: filters.range: Unexpected argument 'polygon'.
24-06-2022 00:46:32 - [ERROR] -  __main__ - (<ipython-input-39-4b0165ac5391>).run_pipeline(line 54) - Pipeline execution failed
Traceback (most recent call last):
  File "<ipython-input-39-4b0165ac5391>", line 50, in run_pipeline
    pipeline.execute()
  File "/home/user/anaconda3/envs/agritech/lib/python3.6/site-packages/pdal/pipeline.py", line 40, in execute
    return self.p.execute()
  File "libpdalpython.pyx", line 180, in pdal.libpdalpython.PyPipeline.execute
RuntimeError: filters.range: Unexpected argument 'polygon'.
24-06-2022 00:46:32 - [ERROR] -  __main__ - (<ipython-input-39-4b0165ac5391>).run_pipeline(line 54) - Pipeline execution failed
Traceback (most recent call last):
  File "<ipython-input-39-4b0165ac5391>", line 50, in run_pipeline
    pipeline.execute()
  File "/home/user/anaconda3/envs/agritech/lib/python3.6/site-packages/pdal/pipeline.py", line 40, in execute
    return self.p.execute()
  File "libpdalpython.pyx", line 180, in pdal.libpdalpython.PyPipeline.execute
RuntimeError: filters.range: Unexpected argument 'polygon'.
24-06-2022 00:46:32 - [ERROR] -  __main__ - (<ipython-input-39-4b0165ac5391>).run_pipeline(line 54) - Pipeline execution failed
Traceback (most recent call last):
  File "<ipython-input-39-4b0165ac5391>", line 50, in run_pipeline
    pipeline.execute()
  File "/home/user/anaconda3/envs/agritech/lib/python3.6/site-packages/pdal/pipeline.py", line 40, in execute
    return self.p.execute()
  File "libpdalpython.pyx", line 180, in pdal.libpdalpython.PyPipeline.execute
RuntimeError: filters.range: Unexpected argument 'polygon'.
24-06-2022 00:46:32 - [ERROR] -  __main__ - (<ipython-input-39-4b0165ac5391>).run_pipeline(line 54) - Pipeline execution failed
Traceback (most recent call last):
  File "<ipython-input-39-4b0165ac5391>", line 50, in run_pipeline
    pipeline.execute()
  File "/home/user/anaconda3/envs/agritech/lib/python3.6/site-packages/pdal/pipeline.py", line 40, in execute
    return self.p.execute()
  File "libpdalpython.pyx", line 180, in pdal.libpdalpython.PyPipeline.execute
RuntimeError: filters.range: Unexpected argument 'polygon'.
24-06-2022 00:46:32 - [ERROR] -  __main__ - (<ipython-input-39-4b0165ac5391>).run_pipeline(line 54) - Pipeline execution failed
Traceback (most recent call last):
  File "<ipython-input-39-4b0165ac5391>", line 50, in run_pipeline
    pipeline.execute()
  File "/home/user/anaconda3/envs/agritech/lib/python3.6/site-packages/pdal/pipeline.py", line 40, in execute
    return self.p.execute()
  File "libpdalpython.pyx", line 180, in pdal.libpdalpython.PyPipeline.execute
RuntimeError: filters.range: Unexpected argument 'polygon'.
24-06-2022 00:46:32 - [ERROR] -  __main__ - (<ipython-input-39-4b0165ac5391>).run_pipeline(line 54) - Pipeline execution failed
Traceback (most recent call last):
  File "<ipython-input-39-4b0165ac5391>", line 50, in run_pipeline
    pipeline.execute()
  File "/home/user/anaconda3/envs/agritech/lib/python3.6/site-packages/pdal/pipeline.py", line 40, in execute
    return self.p.execute()
  File "libpdalpython.pyx", line 180, in pdal.libpdalpython.PyPipeline.execute
RuntimeError: filters.range: Unexpected argument 'polygon'.
24-06-2022 00:46:32 - [ERROR] -  __main__ - (<ipython-input-39-4b0165ac5391>).run_pipeline(line 54) - Pipeline execution failed
Traceback (most recent call last):
  File "<ipython-input-39-4b0165ac5391>", line 50, in run_pipeline
    pipeline.execute()
  File "/home/user/anaconda3/envs/agritech/lib/python3.6/site-packages/pdal/pipeline.py", line 40, in execute
    return self.p.execute()
  File "libpdalpython.pyx", line 180, in pdal.libpdalpython.PyPipeline.execute
RuntimeError: filters.range: Unexpected argument 'polygon'.
24-06-2022 01:39:49 - [INFO] -  files_loader - (files_loader.py).read_json(line 31) - Json file read from fetch.json.
24-06-2022 02:14:35 - [INFO] -  files_loader - (files_loader.py).read_json(line 31) - Json file read from fetch.json.
24-06-2022 02:14:40 - [INFO] -  files_loader - (files_loader.py).read_json(line 31) - Json file read from fetch.json.
24-06-2022 02:14:40 - [INFO] -  files_loader - (files_loader.py).read_json(line 31) - Json file read from fetch.json.
24-06-2022 02:14:44 - [ERROR] -  __main__ - (<ipython-input-3-4b0165ac5391>).run_pipeline(line 54) - Pipeline execution failed
Traceback (most recent call last):
  File "<ipython-input-3-4b0165ac5391>", line 50, in run_pipeline
    pipeline.execute()
  File "/home/user/anaconda3/envs/agritech/lib/python3.6/site-packages/pdal/pipeline.py", line 40, in execute
    return self.p.execute()
  File "libpdalpython.pyx", line 180, in pdal.libpdalpython.PyPipeline.execute
RuntimeError: filters.range: Unexpected argument 'polygon'.
24-06-2022 02:14:44 - [ERROR] -  __main__ - (<ipython-input-3-4b0165ac5391>).run_pipeline(line 54) - Pipeline execution failed
Traceback (most recent call last):
  File "<ipython-input-3-4b0165ac5391>", line 50, in run_pipeline
    pipeline.execute()
  File "/home/user/anaconda3/envs/agritech/lib/python3.6/site-packages/pdal/pipeline.py", line 40, in execute
    return self.p.execute()
  File "libpdalpython.pyx", line 180, in pdal.libpdalpython.PyPipeline.execute
RuntimeError: filters.range: Unexpected argument 'polygon'.
24-06-2022 15:06:31 - [INFO] -  files_loader - (files_loader.py).read_json(line 31) - Json file read from fetch.json.
24-06-2022 15:06:35 - [ERROR] -  __main__ - (<ipython-input-2-4b0165ac5391>).run_pipeline(line 54) - Pipeline execution failed
Traceback (most recent call last):
  File "<ipython-input-2-4b0165ac5391>", line 50, in run_pipeline
    pipeline.execute()
  File "/home/user/anaconda3/envs/agritech/lib/python3.6/site-packages/pdal/pipeline.py", line 40, in execute
    return self.p.execute()
  File "libpdalpython.pyx", line 180, in pdal.libpdalpython.PyPipeline.execute
RuntimeError: filters.range: Unexpected argument 'polygon'.
